<robot
  name="armurdf">
  <link
    name="world_foot_link">
    <inertial>
      <origin
        xyz="-1.277E-17 -3.9505E-20 0.030179"
        rpy="0 0 0" />
      <mass
        value="0.047112" />
      <inertia
        ixx="0"
        ixy="0"
        ixz="0"
        iyy="0"
        iyz="0"
        izz="0" />
    </inertial>
    <visual>
      <origin
        xyz="0 0 0"
        rpy="0 0 0" />
      <geometry>
        <mesh
          filename="package://kv_description/meshes/world_foot_link.stl" />
      </geometry>
      <material
        name="">
        <color
          rgba="1 1 1 1" />
      </material>
    </visual>
    <collision>
      <origin
        xyz="0 0 0"
        rpy="0 0 0" />
      <geometry>
        <mesh
          filename="package://kv_description/meshes/world_foot_link.stl" />
      </geometry>
    </collision>
  </link>
  <link
    name="toe_foot_link">
    <inertial>
      <origin
        xyz="0.0026874 0.094598 0.0043029"
        rpy="0 0 0" />
      <mass
        value="0.19306" />
      <inertia
        ixx="0.00029801"
        ixy="-1.6027E-05"
        ixz="-1.3904E-06"
        iyy="3.0946E-06"
        iyz="-2.5661E-05"
        izz="0.00029666" />
    </inertial>
    <visual>
      <origin
        xyz="0 0 0"
        rpy="0 0 0" />
      <geometry>
        <mesh
          filename="package://kv_description/meshes/toe_foot_link.stl" />
      </geometry>
      <material
        name="">
        <color
          rgba="1 1 1 1" />
      </material>
    </visual>
    <collision>
      <origin
        xyz="0 0 0"
        rpy="0 0 0" />
      <geometry>
        <mesh
          filename="package://kv_description/meshes/toe_foot_link.stl" />
      </geometry>
    </collision>
  </link>
  <joint
    name="toe_foot_joint"
    type="continuous">
    <origin
      xyz="0 -0.06 0"
      rpy="3.1416 0.91035 -7.8821E-17" />
    <parent
      link="world_foot_link" />
    <child
      link="toe_foot_link" />
    <axis
      xyz="0 1 0" />
  </joint>
  <link
    name="foot_thigh_link">
    <inertial>
      <origin
        xyz="-0.0021034 -0.0050999 -0.045876"
        rpy="0 0 0" />
      <mass
        value="0.10494" />
      <inertia
        ixx="0"
        ixy="0"
        ixz="0"
        iyy="0"
        iyz="0"
        izz="0" />
    </inertial>
    <visual>
      <origin
        xyz="0 0 0"
        rpy="0 0 0" />
      <geometry>
        <mesh
          filename="package://kv_description/meshes/foot_thigh_link.stl" />
      </geometry>
      <material
        name="">
        <color
          rgba="1 1 1 1" />
      </material>
    </visual>
    <collision>
      <origin
        xyz="0 0 0"
        rpy="0 0 0" />
      <geometry>
        <mesh
          filename="package://kv_description/meshes/foot_thigh_link.stl" />
      </geometry>
    </collision>
  </link>
  <joint
    name="foot_thigh_joint"
    type="continuous">
    <origin
      xyz="0.024767 0.135 0.024767"
      rpy="3.1342 0.78537 -0.010507" />
    <parent
      link="toe_foot_link" />
    <child
      link="foot_thigh_link" />
    <axis
      xyz="0 0 1" />
  </joint>
  <link
    name="thigh_calf_link">
    <inertial>
      <origin
        xyz="0.00027997 0.12036 0.0040096"
        rpy="0 0 0" />
      <mass
        value="0.7878" />
      <inertia
        ixx="0.0072279"
        ixy="-4.1933E-05"
        ixz="2.8902E-06"
        iyy="6.9814E-05"
        iyz="-6.6258E-05"
        izz="0.0071588" />
    </inertial>
    <visual>
      <origin
        xyz="0 0 0"
        rpy="0 0 0" />
      <geometry>
        <mesh
          filename="package://kv_description/meshes/thigh_calf_link.stl" />
      </geometry>
      <material
        name="">
        <color
          rgba="1 1 1 1" />
      </material>
    </visual>
    <collision>
      <origin
        xyz="0 0 0"
        rpy="0 0 0" />
      <geometry>
        <mesh
          filename="package://kv_description/meshes/thigh_calf_link.stl" />
      </geometry>
    </collision>
  </link>
  <joint
    name="thigh_calf_joint"
    type="continuous">
    <origin
      xyz="0 -0.044415 -0.054974"
      rpy="3.1416 -0.0038068 -1.0114E-15" />
    <parent
      link="foot_thigh_link" />
    <child
      link="thigh_calf_link" />
    <axis
      xyz="0 1 0" />
  </joint>
  <link
    name="calf_big_arm_link">
    <inertial>
      <origin
        xyz="-0.0021034 -0.0050999 -0.045501"
        rpy="0 0 0" />
      <mass
        value="0.10494" />
      <inertia
        ixx="0"
        ixy="0"
        ixz="0"
        iyy="0"
        iyz="0"
        izz="0" />
    </inertial>
    <visual>
      <origin
        xyz="0 0 0"
        rpy="0 0 0" />
      <geometry>
        <mesh
          filename="package://kv_description/meshes/calf_big_arm_link.stl" />
      </geometry>
      <material
        name="">
        <color
          rgba="1 1 1 1" />
      </material>
    </visual>
    <collision>
      <origin
        xyz="0 0 0"
        rpy="0 0 0" />
      <geometry>
        <mesh
          filename="package://kv_description/meshes/calf_big_arm_link.stl" />
      </geometry>
    </collision>
  </link>
  <joint
    name="calf_big_arm_joint"
    type="continuous">
    <origin
      xyz="0 0.31559 -0.035401"
      rpy="1.473E-16 6.0222E-16 -3.1339" />
    <parent
      link="thigh_calf_link" />
    <child
      link="calf_big_arm_link" />
    <axis
      xyz="0 0 -1" />
  </joint>
  <link
    name="big_arm_arm_link">
    <inertial>
      <origin
        xyz="0.00027996 0.11978 0.0040096"
        rpy="0 0 0" />
      <mass
        value="0.7878" />
      <inertia
        ixx="0.0072278"
        ixy="-4.1931E-05"
        ixz="2.8901E-06"
        iyy="6.9814E-05"
        iyz="-6.6259E-05"
        izz="0.0071588" />
    </inertial>
    <visual>
      <origin
        xyz="0 0 0"
        rpy="0 0 0" />
      <geometry>
        <mesh
          filename="package://kv_description/meshes/big_arm_arm_link.stl" />
      </geometry>
      <material
        name="">
        <color
          rgba="1 1 1 1" />
      </material>
    </visual>
    <collision>
      <origin
        xyz="0 0 0"
        rpy="0 0 0" />
      <geometry>
        <mesh
          filename="package://kv_description/meshes/big_arm_arm_link.stl" />
      </geometry>
    </collision>
  </link>
  <joint
    name="big_arm_arm_joint"
    type="continuous">
    <origin
      xyz="0 -0.045 -0.054599"
      rpy="3.1416 -0.0051076 -4.0902E-17" />
    <parent
      link="calf_big_arm_link" />
    <child
      link="big_arm_arm_link" />
    <axis
      xyz="0 1 0" />
  </joint>
  <link
    name="arm_hand_link">
    <inertial>
      <origin
        xyz="0.048329 -0.024492 -0.0013759"
        rpy="0 0 0" />
      <mass
        value="0.16041" />
      <inertia
        ixx="0.00010345"
        ixy="1.4301E-05"
        ixz="-4.5751E-07"
        iyy="2.0848E-06"
        iyz="3.3061E-06"
        izz="0.00010532" />
    </inertial>
    <visual>
      <origin
        xyz="0 0 0"
        rpy="0 0 0" />
      <geometry>
        <mesh
          filename="package://kv_description/meshes/arm_hand_link.stl" />
      </geometry>
      <material
        name="">
        <color
          rgba="1 1 1 1" />
      </material>
    </visual>
    <collision>
      <origin
        xyz="0 0 0"
        rpy="0 0 0" />
      <geometry>
        <mesh
          filename="package://kv_description/meshes/arm_hand_link.stl" />
      </geometry>
    </collision>
  </link>
  <joint
    name="arm_hand_joint"
    type="continuous">
    <origin
      xyz="0 0.315 -0.035719"
      rpy="3.1364 1.5708 0" />
    <parent
      link="big_arm_arm_link" />
    <child
      link="arm_hand_link" />
    <axis
      xyz="-1 0 0" />
  </joint>
  <link
    name="hand_finger_link">
    <inertial>
      <origin
        xyz="-0.0018551 -0.0095131 -0.037375"
        rpy="0 0 0" />
      <mass
        value="0.11897" />
      <inertia
        ixx="0"
        ixy="0"
        ixz="0"
        iyy="0"
        iyz="0"
        izz="0" />
    </inertial>
    <visual>
      <origin
        xyz="0 0 0"
        rpy="0 0 0" />
      <geometry>
        <mesh
          filename="package://kv_description/meshes/hand_finger_link.stl" />
      </geometry>
      <material
        name="">
        <color
          rgba="1 1 1 1" />
      </material>
    </visual>
    <collision>
      <origin
        xyz="0 0 0"
        rpy="0 0 0" />
      <geometry>
        <mesh
          filename="package://kv_description/meshes/hand_finger_link.stl" />
      </geometry>
    </collision>
  </link>
  <joint
    name="hand_finger_joint"
    type="continuous">
    <origin
      xyz="0.054281 -0.0896 0"
      rpy="-1.5708 -1.5553 -4.3394E-13" />
    <parent
      link="arm_hand_link" />
    <child
      link="hand_finger_link" />
    <axis
      xyz="0 0 -1" />
  </joint>
</robot>